Workbook

Sheet Raw Data
A1: OrderID | B1: Date | C1: CustomerID | D1: Product | E1: Quantity | F1: UnitPrice | G1: ShippingAddress | H1: PaymentMethod | I1: OrderStatus | J1: TrackingNumber | K1: ItemsInCart | L1: CouponCode | M1: ReferralSource | N1: TotalPrice
A2: ORD200000 | B2: 44930 | C2: C72649 | D2: Monitor | E2: 5 | F2: 570.62 | G2: 928 Main St | H2: Debit Card | I2: Shipped | J2: TRK37947903 | K2: 7 | L2: SAVE10 | M2: Instagram | N2: 2853.1
A3: ORD200001 | B3: 45527 | C3: C75739 | D3: Phone | E3: 2 | F3: 151.35 | G3: 823 Main St | H3: Online | I3: Shipped | J3: TRK91186779 | K3: 3 | L3: SAVE10 | M3: Referral | N3: 302.7
A4: ORD200002 | B4: 45349 | C4: C81728 | D4: Tablet | E4: 5 | F4: 550.68 | G4: 512 Main St | H4: Credit Card | I4: Cancelled | J4: TRK42903982 | K4: 8 | L4: FREESHIP | M4: Email | N4: 2753.4
A5: ORD200003 | B5: 45214 | C5: C33540 | D5: Chair | E5: 1 | F5: 273.19 | G5: 275 Main St | H5: Debit Card | I5: Returned | J5: TRK62788070 | K5: 5 | L5: SAVE10 | M5: Facebook | N5: 273.19
A6: ORD200004 | B6: 45785 | C6: C81840 | D6: Printer | E6: 4 | F6: 626.01 | G6: 668 Main St | H6: Online | I6: Delivered | J6: TRK29241424 | K6: 8 | L6: SAVE10 | M6: Email | N6: 2504.04
A7: ORD200005 | B7: 45222 | C7: C37249 | D7: Phone | E7: 2 | F7: 245.86 | G7: 934 Main St | H7: Credit Card | I7: Shipped | J7: TRK72976927 | K7: 4 | L7: SAVE10 | M7: Instagram | N7: 491.72
A8: ORD200006 | B8: 45825 | C8: C83492 | D8: Laptop | E8: 1 | F8: 664.42 | G8: 986 Main St | H8: Gift Card | I8: Returned | J8: TRK96417362 | K8: 6 | L8: SAVE10 | M8: Facebook | N8: 664.42
A9: ORD200007 | B9: 45058 | C9: C41460 | D9: Monitor | E9: 5 | F9: 149.55 | G9: 706 Main St | H9: Cash | I9: Shipped | J9: TRK78809193 | K9: 9 | L9: FREESHIP | M9: Facebook | N9: 747.75
A10: ORD200008 | B10: 45749 | C10: C26817 | D10: Phone | E10: 2 | F10: 134.28 | G10: 904 Main St | H10: Gift Card | I10: Cancelled | J10: TRK61042692 | K10: 2 | M10: Email | N10: 268.56
A11: ORD200009 | B11: 45251 | C11: C31946 | D11: Desk | E11: 4 | F11: 509.38 | G11: 102 Main St | H11: Credit Card | I11: Shipped | J11: TRK33478363 | K11: 6 | L11: SAVE10 | M11: Google | N11: 2037.52
A12: ORD200010 | B12: 45289 | C12: C43443 | D12: Tablet | E12: 5 | F12: 625.97 | G12: 333 Main St | H12: Credit Card | I12: Returned | J12: TRK98859248 | K12: 9 | L12: WINTER15 | M12: Instagram | N12: 3129.85
A13: ORD200011 | B13: 45339 | C13: C93861 | D13: Monitor | E13: 3 | F13: 49.14 | G13: 831 Main St | H13: Online | I13: Returned | J13: TRK48234646 | K13: 7 | L13: SAVE10 | M13: Email | N13: 147.42
A14: ORD200012 | B14: 45580 | C14: C38785 | D14: Monitor | E14: 2 | F14: 180.5 | G14: 179 Main St | H14: Debit Card | I14: Pending | J14: TRK20419991 | K14: 6 | L14: FREESHIP | M14: Referral | N14: 361
A15: ORD200013 | B15: 45168 | C15: C88348 | D15: Laptop | E15: 3 | F15: 201.49 | G15: 903 Main St | H15: Credit Card | I15: Returned | J15: TRK81913874 | K15: 4 | L15: FREESHIP | M15: Facebook | N15: 604.47
A16: ORD200014 | B16: 45012 | C16: C98474 | D16: Tablet | E16: 2 | F16: 393.33 | G16: 980 Main St | H16: Debit Card | I16: Pending | J16: TRK79186539 | K16: 3 | L16: SAVE10 | M16: Instagram | N16: 786.66
A17: ORD200015 | B17: 45124 | C17: C39416 | D17: Printer | E17: 1 | F17: 473.96 | G17: 942 Main St | H17: Cash | I17: Delivered | J17: TRK54930938 | K17: 3 | M17: Google | N17: 473.96
A18: ORD200016 | B18: 44950 | C18: C28976 | D18: Printer | E18: 2 | F18: 533.81 | G18: 914 Main St | H18: Credit Card | I18: Pending | J18: TRK13194259 | K18: 3 | L18: FREESHIP | M18: Email | N18: 1067.62
A19: ORD200017 | B19: 45353 | C19: C60672 | D19: Tablet | E19: 1 | F19: 423.4 | G19: 382 Main St | H19: Debit Card | I19: Shipped | J19: TRK11972116 | K19: 3 | M19: Referral | N19: 423.4
A20: ORD200018 | B20: 45742 | C20: C84329 | D20: Desk | E20: 1 | F20: 431.44 | G20: 891 Main St | H20: Gift Card | I20: Pending | J20: TRK65191045 | K20: 3 | L20: SAVE10 | M20: Facebook | N20: 431.44
A21: ORD200019 | B21: 44949 | C21: C14552 | D21: Monitor | E21: 5 | F21: 224 | G21: 273 Main St | H21: Cash | I21: Returned | J21: TRK59101365 | K21: 9 | L21: SAVE10 | M21: Google | N21: 1120
A22: ORD200020 | B22: 45054 | C22: C54829 | D22: Chair | E22: 5 | F22: 62.51 | G22: 587 Main St | H22: Cash | I22: Pending | J22: TRK16718651 | K22: 9 | L22: WINTER15 | M22: Instagram | N22: 312.55
A23: ORD200021 | B23: 45613 | C23: C99023 | D23: Monitor | E23: 4 | F23: 342.95 | G23: 569 Main St | H23: Cash | I23: Delivered | J23: TRK52646983 | K23: 6 | M23: Google | N23: 1371.8
A24: ORD200022 | B24: 44955 | C24: C34416 | D24: Monitor | E24: 2 | F24: 49.62 | G24: 633 Main St | H24: Online | I24: Pending | J24: TRK75937350 | K24: 2 | L24: SAVE10 | M24: Google | N24: 99.24
A25: ORD200023 | B25: 45756 | C25: C42372 | D25: Phone | E25: 4 | F25: 273.25 | G25: 755 Main St | H25: Debit Card | I25: Cancelled | J25: TRK36168083 | K25: 5 | L25: FREESHIP | M25: Referral | N25: 1093
A26: ORD200024 | B26: 45595 | C26: C17470 | D26: Laptop | E26: 2 | F26: 230.95 | G26: 956 Main St | H26: Online | I26: Delivered | J26: TRK28775057 | K26: 3 | L26: WINTER15 | M26: Referral | N26: 461.9
A27: ORD200025 | B27: 45497 | C27: C42577 | D27: Monitor | E27: 1 | F27: 399.98 | G27: 709 Main St | H27: Debit Card | I27: Delivered | J27: TRK69423327 | K27: 3 | L27: WINTER15 | M27: Email | N27: 399.98
A28: ORD200026 | B28: 45357 | C28: C21944 | D28: Laptop | E28: 5 | F28: 59.55 | G28: 296 Main St | H28: Online | I28: Delivered | J28: TRK80276812 | K28: 6 | M28: Referral | N28: 297.75
A29: ORD200027 | B29: 45344 | C29: C97593 | D29: Printer | E29: 1 | F29: 472.74 | G29: 881 Main St | H29: Online | I29: Shipped | J29: TRK89117573 | K29: 6 | L29: WINTER15 | M29: Google | N29: 472.74
A30: ORD200028 | B30: 45251 | C30: C59823 | D30: Phone | E30: 4 | F30: 160.07 | G30: 568 Main St | H30: Online | I30: Pending | J30: TRK65895539 | K30: 5 | M30: Email | N30: 640.28
A31: ORD200029 | B31: 45555 | C31: C33260 | D31: Desk | E31: 3 | F31: 423.53 | G31: 930 Main St | H31: Credit Card | I31: Delivered | J31: TRK59744090 | K31: 6 | L31: SAVE10 | M31: Referral | N31: 1270.59
A32: ORD200030 | B32: 45738 | C32: C44267 | D32: Monitor | E32: 2 | F32: 426.7 | G32: 895 Main St | H32: Online | I32: Pending | J32: TRK54751444 | K32: 5 | L32: SAVE10 | M32: Referral | N32: 853.4
A33: ORD200031 | B33: 45107 | C33: C26445 | D33: Chair | E33: 3 | F33: 500.08 | G33: 996 Main St | H33: Debit Card | I33: Returned | J33: TRK31229981 | K33: 6 | M33: Facebook | N33: 1500.24
A34: ORD200032 | B34: 45047 | C34: C12388 | D34: Tablet | E34: 5 | F34: 536.72 | G34: 830 Main St | H34: Cash | I34: Delivered | J34: TRK99261395 | K34: 10 | M34: Email | N34: 2683.6
A35: ORD200033 | B35: 45082 | C35: C52184 | D35: Chair | E35: 1 | F35: 162.77 | G35: 912 Main St | H35: Online | I35: Cancelled | J35: TRK73312471 | K35: 4 | L35: WINTER15 | M35: Facebook | N35: 162.77
A36: ORD200034 | B36: 44933 | C36: C67195 | D36: Chair | E36: 4 | F36: 576.52 | G36: 926 Main St | H36: Credit Card | I36: Pending | J36: TRK55467915 | K36: 5 | L36: WINTER15 | M36: Facebook | N36: 2306.08
A37: ORD200035 | B37: 45633 | C37: C50304 | D37: Monitor | E37: 2 | F37: 465.15 | G37: 128 Main St | H37: Online | I37: Shipped | J37: TRK46850888 | K37: 2 | L37: SAVE10 | M37: Facebook | N37: 930.3
A38: ORD200036 | B38: 45785 | C38: C59337 | D38: Laptop | E38: 2 | F38: 534.43 | G38: 465 Main St | H38: Debit Card | I38: Pending | J38: TRK50961250 | K38: 5 | M38: Facebook | N38: 1068.86
A39: ORD200037 | B39: 45579 | C39: C10054 | D39: Laptop | E39: 2 | F39: 76.74 | G39: 409 Main St | H39: Cash | I39: Returned | J39: TRK94005261 | K39: 7 | L39: SAVE10 | M39: Instagram | N39: 153.48
A40: ORD200038 | B40: 45645 | C40: C15924 | D40: Laptop | E40: 1 | F40: 245.89 | G40: 549 Main St | H40: Debit Card | I40: Delivered | J40: TRK14835975 | K40: 3 | L40: SAVE10 | M40: Google | N40: 245.89
...

Sheet Cleaned Data
A1: Order_ID | B1: Date | C1: Customer_ID | D1: Product | E1: Quantity | F1: Unit_Price | G1: Shipping_Address | H1: Payment_Method | I1: Order_Status | J1: Tracking_Number | K1: ItemsIn_Cart | L1: Coupon_Code | M1: Referral_Source | N1: Total_Price
A2: ORD200000 | B2: 44930 | C2: C72649 | D2: Monitor | E2: 5 | F2: 570.62 | G2: 928 Main St | H2: Debit Card | I2: Shipped | J2: TRK37947903 | K2: 7 | L2: SAVE10 | M2: Instagram | N2: 2853.1
A3: ORD200001 | B3: 45527 | C3: C75739 | D3: Phone | E3: 2 | F3: 151.35 | G3: 823 Main St | H3: Online | I3: Shipped | J3: TRK91186779 | K3: 3 | L3: SAVE10 | M3: Referral | N3: 302.7
A4: ORD200002 | B4: 45349 | C4: C81728 | D4: Tablet | E4: 5 | F4: 550.68 | G4: 512 Main St | H4: Credit Card | I4: Cancelled | J4: TRK42903982 | K4: 8 | L4: FREESHIP | M4: Email | N4: 2753.4
A5: ORD200003 | B5: 45214 | C5: C33540 | D5: Chair | E5: 1 | F5: 273.19 | G5: 275 Main St | H5: Debit Card | I5: Returned | J5: TRK62788070 | K5: 5 | L5: SAVE10 | M5: Facebook | N5: 273.19
A6: ORD200004 | B6: 45785 | C6: C81840 | D6: Printer | E6: 4 | F6: 626.01 | G6: 668 Main St | H6: Online | I6: Delivered | J6: TRK29241424 | K6: 8 | L6: SAVE10 | M6: Email | N6: 2504.04
A7: ORD200005 | B7: 45222 | C7: C37249 | D7: Phone | E7: 2 | F7: 245.86 | G7: 934 Main St | H7: Credit Card | I7: Shipped | J7: TRK72976927 | K7: 4 | L7: SAVE10 | M7: Instagram | N7: 491.72
A8: ORD200006 | B8: 45825 | C8: C83492 | D8: Laptop | E8: 1 | F8: 664.42 | G8: 986 Main St | H8: Gift Card | I8: Returned | J8: TRK96417362 | K8: 6 | L8: SAVE10 | M8: Facebook | N8: 664.42
A9: ORD200007 | B9: 45058 | C9: C41460 | D9: Monitor | E9: 5 | F9: 149.55 | G9: 706 Main St | H9: Cash | I9: Shipped | J9: TRK78809193 | K9: 9 | L9: FREESHIP | M9: Facebook | N9: 747.75
A10: ORD200008 | B10: 45749 | C10: C26817 | D10: Phone | E10: 2 | F10: 134.28 | G10: 904 Main St | H10: Gift Card | I10: Cancelled | J10: TRK61042692 | K10: 2 | L10: NO COUPON | M10: Email | N10: 268.56
A11: ORD200009 | B11: 45251 | C11: C31946 | D11: Desk | E11: 4 | F11: 509.38 | G11: 102 Main St | H11: Credit Card | I11: Shipped | J11: TRK33478363 | K11: 6 | L11: SAVE10 | M11: Google | N11: 2037.52
A12: ORD200010 | B12: 45289 | C12: C43443 | D12: Tablet | E12: 5 | F12: 625.97 | G12: 333 Main St | H12: Credit Card | I12: Returned | J12: TRK98859248 | K12: 9 | L12: WINTER15 | M12: Instagram | N12: 3129.85
A13: ORD200011 | B13: 45339 | C13: C93861 | D13: Monitor | E13: 3 | F13: 49.14 | G13: 831 Main St | H13: Online | I13: Returned | J13: TRK48234646 | K13: 7 | L13: SAVE10 | M13: Email | N13: 147.42
... A1201: ORD201199 | B1201: 45088 | C1201: C57502 | D1201: Tablet | E1201: 4 | F1201: 560.58 | G1201: 201 Main St | H1201: Gift Card | I1201: Returned | J1201: TRK51116746 | K1201: 6 | L1201: SAVE10 | M1201: Referral | N1201: 2242.32

Sheet EDA
A11: Mean | B11: =AVERAGE('Cleaned Data'!N:N) -> 1053.9683 | D11: Mean | E11: =AVERAGE('Cleaned Data'!F2:F1201) -> 356.41275 | G11: Mean | H11: =AVERAGE('Cleaned Data'!E2:E1201) -> 2.9458333
A12: Standard Error | B12: =STDEV('Cleaned Data'!N2:N1201)/SQRT(COUNT('Cleaned Data'!N2:N1201)) -> 23.66722 | D12: Standard Error | E12: =STDEV('Cleaned Data'!F2:F1201)/SQRT(COUNT('Cleaned Data'!F2:F1201)) -> 5.6920139 | G12: Standard Error | H12: =STDEV('Cleaned Data'!E2:E1201)/SQRT(COUNT('Cleaned Data'!E2:E1201)) -> 0.040632673
A13: Median | B13: =MEDIAN('Cleaned Data'!N:N) -> 823.615 | D13: Median | E13: =MEDIAN('Cleaned Data'!F2:F1201) -> 364.21 | G13: Median | H13: =MEDIAN('Cleaned Data'!E2:E1201) -> 3
A14: Mode | B14: =MODE('Cleaned Data'!N2:N1201) -> 635.9 | D14: Mode | E14: =MODE('Cleaned Data'!F2:F1201) -> 127.18 | G14: Mode | H14: =MODE('Cleaned Data'!E2:E1201) -> 1
A15: Standard Deviation | B15: =STDEV('Cleaned Data'!N2:N1201) -> 819.85656 | D15: Standard Deviation | E15: =STDEV('Cleaned Data'!F2:F1201) -> 197.17715 | G15: Standard Deviation | H15: =STDEV('Cleaned Data'!E2:E1201) -> 1.4075571
A16: Sample Variance | B16: =VAR('Cleaned Data'!N2:N1201) -> 672164.78 | D16: Sample Variance | E16: =VAR('Cleaned Data'!F2:F1201) -> 38878.827 | G16: Sample Variance | H16: =VAR('Cleaned Data'!E2:E1201) -> 1.981217
A17: Kurtosis | B17: =KURT('Cleaned Data'!N2:N1201) -> -0.040414717 | D17: Kurtosis | E17: =KURT('Cleaned Data'!F2:F1201) -> -1.1910109 | G17: Kurtosis | H17: =KURT('Cleaned Data'!E2:E1201) -> -1.2945959
A18: Skewness | B18: =SKEW('Cleaned Data'!N2:N1201) -> 0.89135908 | D18: Skewness | E18: =SKEW('Cleaned Data'!F2:F1201) -> -0.026511641 | G18: Skewness | H18: =SKEW('Cleaned Data'!E2:E1201) -> 0.027922314
A19: Range | B19: =MAX('Cleaned Data'!N2:N1201)-MIN('Cleaned Data'!N2:N1201) -> 3445.01 | D19: Range | E19: =MAX('Cleaned Data'!F2:F1201)-MIN('Cleaned Data'!F2:F1201) -> 688.54 | G19: Range | H19: =MAX('Cleaned Data'!E2:E1201)-MIN('Cleaned Data'!E2:E1201) -> 4
A20: Min | B20: =MIN('Cleaned Data'!N:N) -> 11.39 | D20: Min | E20: =MIN('Cleaned Data'!F2:F1201) -> 11.39 | G20: Min | H20: =MIN('Cleaned Data'!E2:E1201) -> 1
A21: Max | B21: =MAX('Cleaned Data'!N:N) -> 3456.4 | D21: Max | E21: =MAX('Cleaned Data'!F2:F1201) -> 699.93 | G21: Max | H21: =MAX('Cleaned Data'!E2:E1201) -> 5
A22: Sum | B22: =SUM('Cleaned Data'!N2:N1201) -> 1264762 | D22: Sum | E22: =SUM('Cleaned Data'!F2:F1201) -> 427695.3 | G22: Sum | H22: =SUM('Cleaned Data'!E2:E1201) -> 3535
A23: Count | B23: =COUNTA('Cleaned Data'!A:A)-1 -> 1200 | D23: Count | E23: =COUNT('Cleaned Data'!F2:F1201) -> 1200 | G23: Count | H23: =COUNT('Cleaned Data'!E2:E1201) -> 1200
B31: Monitor | C31: =COUNTIF('Cleaned Data'!D2:D1201,"Monitor") -> 163 | D31: =SUMIF('Cleaned Data'!D2:D1201,"Monitor",'Cleaned Data'!E2:E1201) -> 480 | E31: =SUMIF('Cleaned Data'!D2:D1201,"Monitor",'Cleaned Data'!N2:N1201) -> 175651.41
B32: Phone | C32: =COUNTIF('Cleaned Data'!D2:D1201,"Phone") -> 156 | D32: =SUMIF('Cleaned Data'!D2:D1201,"Phone",'Cleaned Data'!E2:E1201) -> 411 | E32: =SUMIF('Cleaned Data'!D2:D1201,"Phone",'Cleaned Data'!N2:N1201) -> 151722.39
B33: Laptop | C33: =COUNTIF('Cleaned Data'!D2:D1201,"Laptop") -> 173 | D33: =SUMIF('Cleaned Data'!D2:D1201,"Laptop",'Cleaned Data'!E2:E1201) -> 535 | E33: =SUMIF('Cleaned Data'!D2:D1201,"Laptop",'Cleaned Data'!N2:N1201) -> 192126.56
B34: Tablet | C34: =COUNTIF('Cleaned Data'!D2:D1201,"Tablet") -> 179 | D34: =SUMIF('Cleaned Data'!D2:D1201,"Tablet",'Cleaned Data'!E2:E1201) -> 497 | E34: =SUMIF('Cleaned Data'!D2:D1201,"Tablet",'Cleaned Data'!N2:N1201) -> 186568.95
B35: Chair | C35: =COUNTIF('Cleaned Data'!D2:D1201,"Chair") -> 178 | D35: =SUMIF('Cleaned Data'!D2:D1201,"Chair",'Cleaned Data'!E2:E1201) -> 562 | E35: =SUMIF('Cleaned Data'!D2:D1201,"Chair",'Cleaned Data'!N2:N1201) -> 195620.11
B36: Desk | C36: =COUNTIF('Cleaned Data'!D2:D1201,"Desk") -> 170 | D36: =SUMIF('Cleaned Data'!D2:D1201,"Desk",'Cleaned Data'!E2:E1201) -> 508 | E36: =SUMIF('Cleaned Data'!D2:D1201,"Desk",'Cleaned Data'!N2:N1201) -> 167459.93
B37: Printer | C37: =COUNTIF('Cleaned Data'!D2:D1201,"Printer") -> 181 | D37: =SUMIF('Cleaned Data'!D2:D1201,"Printer",'Cleaned Data'!E2:E1201) -> 542 | E37: =SUMIF('Cleaned Data'!D2:D1201,"Printer",'Cleaned Data'!N2:N1201) -> 195612.61
M44: \

Sheet Summary & Observation 
A6: Q1 | B6: =QUARTILE('Cleaned Data'!N2:N1201,1) -> 410.52 | C6: ORD200107 | D6: Printer | E6: 5 | F6: 3353.75
A7: Q3 | B7: =QUARTILE('Cleaned Data'!N2:N1201,3) -> 1578.475 | C7: ORD200326 | D7: Laptop | E7: 5 | F7: 3352.4
A8: IQR | B8: =B7-B6 -> 1167.955 | C8: ORD200328 | D8: Tablet | E8: 5 | F8: 3370.2
A9: LOWER BOUND | B9: =B6-(1.5*B8) -> -1341.4125 | C9: ORD200469 | D9: Chair | E9: 5 | F9: 3384.9
A10: UPPER BOUND | B10: =B7+(1.5*B8) -> 3330.4075 | C10: ORD200632 | D10: Laptop | E10: 5 | F10: 3390.8
C11: ORD200789 | D11: Tablet | E11: 5 | F11: 3456.4
C12: ORD201065 | D12: Printer | E12: 5 | F12: 3334
C13: ORD201122 | D13: Monitor | E13: 5 | F13: 3390.95
B20: Instagram | C20: =COUNTIF('Cleaned Data'!M2:M1201,"Instagram") -> 259 | D20: =SUMIF('Cleaned Data'!M2:M1201,"Instagram",'Cleaned Data'!E2:E1201) -> 770 | E20: =SUMIF('Cleaned Data'!M2:M1201,"Instagram",'Cleaned Data'!N2:N1201) -> 275285.45 | F20: =AVERAGEIF('Cleaned Data'!M2:M1201,"Instagram",'Cleaned Data'!K2:K1201) -> 5.5019305
B21: Facebook | C21: =COUNTIF('Cleaned Data'!M2:M1201,"Facebook") -> 228 | D21: =SUMIF('Cleaned Data'!M2:M1201,"Facebook",'Cleaned Data'!E2:E1201) -> 674 | E21: =SUMIF('Cleaned Data'!M2:M1201,"Facebook",'Cleaned Data'!N2:N1201) -> 250410.9 | F21: =AVERAGEIF('Cleaned Data'!M2:M1201,"Facebook",'Cleaned Data'!K2:K1201) -> 5.3333333
B22: Email | C22: =COUNTIF('Cleaned Data'!M2:M1201,"Email") -> 250 | D22: =SUMIF('Cleaned Data'!M2:M1201,"Email",'Cleaned Data'!E2:E1201) -> 746 | E22: =SUMIF('Cleaned Data'!M2:M1201,"Email",'Cleaned Data'!N2:N1201) -> 261808.55 | F22: =AVERAGEIF('Cleaned Data'!M2:M1201,"Email",'Cleaned Data'!K2:K1201) -> 5.6
B23: Referral | C23: =COUNTIF('Cleaned Data'!M2:M1201,"Referral") -> 222 | D23: =SUMIF('Cleaned Data'!M2:M1201,"Referral",'Cleaned Data'!E2:E1201) -> 631 | E23: =SUMIF('Cleaned Data'!M2:M1201,"Referral",'Cleaned Data'!N2:N1201) -> 226815.58 | F23: =AVERAGEIF('Cleaned Data'!M2:M1201,"Referral",'Cleaned Data'!K2:K1201) -> 5.3963964
B24: Google | C24: =COUNTIF('Cleaned Data'!M2:M1201,"Google") -> 241 | D24: =SUMIF('Cleaned Data'!M2:M1201,"Google",'Cleaned Data'!E2:E1201) -> 714 | E24: =SUMIF('Cleaned Data'!M2:M1201,"Google",'Cleaned Data'!N2:N1201) -> 250441.48 | F24: =AVERAGEIF('Cleaned Data'!M2:M1201,"Google",'Cleaned Data'!K2:K1201) -> 5.5726141
B32: Freeship | C32: =COUNTIF('Cleaned Data'!L2:L1201,"FREESHIP") -> 313 | D32: =SUMIF('Cleaned Data'!L2:L1201,"FREESHIP",'Cleaned Data'!N2:N1201) -> 335036.99 | E32: =AVERAGEIF('Cleaned Data'!L2:L1201,"FREESHIP",'Cleaned Data'!N2:N1201) -> 1070.4057
B33: No Coupon | C33: =COUNTIF('Cleaned Data'!L2:L1201,"NO COUPON") -> 309 | D33: =SUMIF('Cleaned Data'!L2:L1201,"NO COUPON",'Cleaned Data'!N2:N1201) -> 322401.41 | E33: =AVERAGEIF('Cleaned Data'!L2:L1201,"NO COUPON",'Cleaned Data'!N2:N1201) -> 1043.3703
B34: Save10 | C34: =COUNTIF('Cleaned Data'!L2:L1201,"SAVE10") -> 286 | D34: =SUMIF('Cleaned Data'!L2:L1201,"SAVE10",'Cleaned Data'!N2:N1201) -> 304840.02 | E34: =AVERAGEIF('Cleaned Data'!L2:L1201,"SAVE10",'Cleaned Data'!N2:N1201) -> 1065.8742
B35: Winter15 | C35: =COUNTIF('Cleaned Data'!L2:L1201,"WINTER15") -> 292 | D35: =SUMIF('Cleaned Data'!L2:L1201,"WINTER15",'Cleaned Data'!N2:N1201) -> 302483.54 | E35: =AVERAGEIF('Cleaned Data'!L2:L1201,"WINTER15",'Cleaned Data'!N2:N1201) -> 1035.9025

Sheet KEY OBSERVATION
A4: Dataset Overview
A6: This analysis was carried out on an e-commerce dataset containing 1,200 orders across 14 columns. The goal was to understand patterns, trends, and distributions within the data.
A10: 1. General Order Patterns
A12: The average order value was $1,053.97 while the median was $823.62. The difference between these two figures suggests that a small number of high-value orders are pulling the average upward. Most customers ordered between 1 to 5 items, with 3 being the most common quantity.
A16: 2. Product Performance
A18: Printer and Chair were the top performing categories, generating revenues of $195,612.61 and $195,620.11 respectively. Phone was the lowest performing product with only $151,722.39 in revenue and 156 orders. Overall, revenue was fairly balanced across all product categories, indicating consistent customer demand.
A22: 3. Outliers
A24: Eight orders were identified as statistical outliers, all with a Total Price above $3,330.41. Interestingly, all outlier orders had a quantity of 5 items, suggesting that bulk purchases are the main driver of unusually high order values.
A27: 4. Customer & Referral Performance
A29: Instagram was the strongest customer acquisition channel, bringing in 259 orders and $275,285.45 in revenue. The Referral channel had the lowest performance with 222 orders and $226,815.58 in revenue. Average cart size was consistent across all channels, ranging between 5.3 and 5.6 items.
A33: 5. Discount Code Performance
A35: FREESHIP was the most popular coupon code with 313 orders and $335,036.99 in revenue. SAVE10 had the least usage with 286 orders. Despite differences in order count, average order values were similar across all coupon codes, ranging between $1,035 and $1,070, suggesting discounts did not significantly affect spending behavior.
... A41: The business shows healthy and balanced performance across products and channels. Instagram should be prioritized as a marketing channel. Printer and Chair categories deserve more investment. The FREESHIP coupon is clearly the most attractive offer to customers.
